Workbook

Sheet はじめに
B2: 選手フィードバックシート（TI選手 2026/07/22〜2026/10/05）
B4: ■ シート構成
B5: ① サマリー … 主要KPI（前期間 3/30〜5/22 との比較つき）と、コーチ/選手の記入欄。これだけ印刷して渡してもOK。
B6: ② 日次統合データ … 4項目を1行に統合した表。色分けで「悪い日」「良い日」が一目でわかる。
B7: ③ 食事バランス … タンパク源(魚/肉/豆/卵)を昼夕別にカレンダー表示。偏りが視覚化される。
B8: ④ トレンドグラフ … 体重・RPE/疲労・睡眠・週間練習時間を時系列グラフで表示。会話のたたき台に。
B9: ⑤ 関連性ヒント … 前回と同じ観点を今期間データで再計算し、前回との比較（再現したか）も表示。今期間の追加分析（暑さ・長時間練習など）はSection D。
B10: データ_xxxx … アプリから出力した元データ（7/22〜10/5）。
B12: ■ 今回の集計ルール（前回からの変更点）
B13: ・今期間から「ウエイトトレーニング」が加わり、1日に2セッションある日（7/24・7/27・9/3・9/10）がある。
B14: ② 日次統合データでは1日1行にまとめ、練習時間＝合計、RPE・運動後疲労＝その日の最大値、瞬発力・持久力＝実践トレーニングの値 としている。
B15: ・記録のない日（8/3、8/5〜8/10、8/19、8/21、10/1、10/3、10/5）は集計対象外。期間76日のうち記録日数は64日。
... B30: ・栄養バランス: 入力規則に依存。アプリ仕様に合わせて読み替え。

Sheet ① サマリー
B2: TI選手 フィードバックレポート
B4: 選手名 | C4: TI選手 | F4: 対象期間 | G4: 2026/07/22 〜 2026/10/05
B5: 記録日数 | C5: =COUNTA('② 日次統合データ'!A4:A67)&"日（期間76日中）" -> 64日（期間76日中） | F5: レポート作成日 | G5: 2026/10/05
F6: 比較対象（前期間） | G6: 2026/03/30 〜 2026/05/22
B8: ■ 期間サマリー
B9: 指標 | C9: 今期間 | D9: 前期間 | E9: 変化 | F9: 評価目安 | G9: 備考
B10: 総トレーニング日数(休養除く) | C10: =COUNTIF('② 日次統合データ'!B4:B67,"<>休養日") -> 52 | D10: 45 | E10: — | F10: 休養日とのバランスを確認 | G10: 記録64日中52日（前回53日中45日）。練習頻度は同程度
B11: 休養日数 | C11: =COUNTIF('② 日次統合データ'!B4:B67,"休養日") -> 12 | D11: 8 | E11: — | F11: 週1日程度が目安 | G11: 9月後半〜10月は休養日を増やせている
B12: 総トレーニング時間(分) | C12: =SUM('② 日次統合データ'!C4:C67) -> 5470 | D12: 4530 | E12: — | F12: 前週との比較で過負荷を確認 | G12: 9/14週が960分で最多（④の週間グラフ参照）
B13: 1回あたり平均練習時間(分) | C13: =SUM('② 日次統合データ'!C4:C67)/COUNTIF('② 日次統合データ'!B4:B67,"<>休養日") -> 105.19231 | D13: 100.66667 | E13: =C13-D13 -> 4.525641 | F13: 急激な増加は怪我リスク | G13: 180分の長時間練習が11回（9月に集中）
B14: ウエイトトレーニング実施日数 | C14: =COUNTIF('② 日次統合データ'!B4:B67,"*ウエイト*") -> 4 | D14: 0 | E14: — | F14: 新たに導入 | G14: 7/24〜導入。「扱う重量に慣れてきた」(7/27)
B15: 平均RPE(練習日のみ) | C15: =AVERAGE('② 日次統合データ'!D4:D67) -> 6.5384615 | D15: 6.4 | E15: =C15-D15 -> 0.13846154 | F15: 6〜7が中強度の目安 | G15: RPEの高い日が続く時は、回復についても意識！
B16: 平均運動後疲労(練習日のみ) | C16: =AVERAGE('② 日次統合データ'!G4:G67) -> 3.3846154 | D16: 3.5555556 | E16: =C16-D16 -> -0.17094017 | F16: 低いほど回復良好 | G16: 前回より改善。ただし疲労5の日が4回（9/7・9/17・9/19・9/24）
B17: 平均睡眠時間(h) | C17: =AVERAGE('② 日次統合データ'!K4:K67) -> 6.71875 | D17: 7.1603774 | E17: =C17-D17 -> -0.44162736 | F17: 7時間以上が目安 | G17: 前回より約0.4h減少。遠征前後（8/2〜8/12）に5h以下が集中
B18: 睡眠7時間未満の日数 | C18: =COUNTIF('② 日次統合データ'!K4:K67,"<7") -> 14 | D18: 8 | E18: — | F18: 少ないほど良い | G18: 前回8日→14日。6h未満の日は起床時CDが悪化（⑤参照）
B19: 平均睡眠の質(1=良/5=悪) | C19: =AVERAGE('② 日次統合データ'!J4:J67) -> 2.359375 | D19: 2.509434 | E19: =C19-D19 -> -0.15005896 | F19: 2以下が望ましい | G19: 改善傾向！高い日は前夜の行動を振り返る（食事、スマホ等）
B20: 平均起床時コンディション(1=良/5=悪) | C20: =AVERAGE('② 日次統合データ'!I4:I67) -> 2.359375 | D20: 2.5849057 | E20: =C20-D20 -> -0.22553066 | F20: 2以下が望ましい | G20: 改善傾向！主観の悪化は早期の疲労サイン
B21: 平均体重(kg) | C21: =AVERAGE('② 日次統合データ'!H4:H67) -> 62.467213 | D21: 61.31875 | E21: =C21-D21 -> 1.1484631 | F21: ±1kg以内の変動が目安 | G21: 前回比+1.2kg。8月後半以降は62〜63kg台で推移
B22: 体重変動幅(kg) | C22: =MAX('② 日次統合データ'!H4:H67)-MIN('② 日次統合データ'!H4:H67) -> 2.4 | D22: 1.6 | E22: =C22-D22 -> 0.8 | F22: 1.5kg以内が目安 | G22: 61.1〜63.5kg。日々の変動も大きめ→測定条件の統一を
B23: 平均水分摂取量(ml) | C23: =AVERAGE('② 日次統合データ'!N4:N67) -> 914.0625 | D23: 896.22642 | E23: =C23-D23 -> 17.836085 | F23: 1000ml以上が目安 | G23: 休養日は500mlの日が多い（休養日12日中8日）
B24: 水分1000ml以上の日数 | C24: =COUNTIF('② 日次統合データ'!N4:N67,">=1000") -> 52 | D24: 42 | E24: — | G24: 64日中52日（81%）。前回79%
B25: 練習後補食「はい」の日数 | C25: =COUNTIF('② 日次統合データ'!L4:L67,"はい") -> 36 | D25: 32 | E25: — | F25: 練習日は毎回が理想 | G25: 回復速度に関連しうる
B26: 練習日の補食実施率 | C26: =COUNTIFS('② 日次統合データ'!B4:B67,"<>休養日",'② 日次統合データ'!L4:L67,"はい")/COUNTIF('② 日次統合データ'!B4:B67,"<>休養日") -> 0.69230769 | D26: 0.71111111 | E26: =C26-D26 -> -0.018803419 | F26: 100%が理想 | G26: 9/1〜9/11は100%！一方9/12〜9/19は14%に急落
B27: きのこ・海藻「はい」の日数 | C27: =COUNTIF(データ_食事!E4:E67,"はい") -> 54 | D27: 35 | E27: — | F27: 週4日以上を目標 | G27: 64日中54日！ほぼ毎日摂れていて素晴らしい
B28: タンパク質平均種類数(昼夕合計) | C28: ='③ 食事バランス'!J70 -> 3.1875 | D28: 2.2830189 | E28: =C28-D28 -> 0.90448113 | F28: 1.5以上で多様性◎ | G28: 大幅改善！夕食の豆・卵が増えた
B29: 昼食タンパク質平均種類数 | C29: =COUNTIF('③ 食事バランス'!B6:E69,"○")/COUNT('③ 食事バランス'!A6:A69) -> 0.90625 | D29: 0.67924528 | E29: =C29-D29 -> 0.22700472 | F29: 1.0以上が目安 | G29: 改善中。昼の魚・豆が引き続き少ない
B30: 夕食タンパク質平均種類数 | C30: =COUNTIF('③ 食事バランス'!F6:I69,"○")/COUNT('③ 食事バランス'!A6:A69) -> 2.28125 | D30: 1.6037736 | E30: =C30-D30 -> 0.67747642 | F30: 2.0以上が目安 | G30: 前回1.60→2.28と大きく向上
B31: ※「変化」の色：緑＝前回より改善／オレンジ＝前回より悪化。日数の指標は期間の長さが違うため変化は表示していません。
B33: ■ 今期間のハイライト（コーチ記入欄）
B34: ① よかった点（継続したい行動）
B35: ◯ 食事の「多様性」が大きく前進！タンパク質の種類数は平均2.28→3.19種/日、夕食は1.60→2.28種に。前回弱点だった夕食の豆（15→25日）・卵（15→38日）がしっかり増え、種類数0〜1の日は64日中4日だけでした。きのこ・海藻も64日中54日とほぼ毎日摂れています。 ◯ 前回の目標「練習後の補食」は、9/1〜9/11の期間で練習日10日すべて「はい」（100%）。この期間はRPE8の練習（9/4・9/8）が入っても疲労は3〜4に収まっており、「やればできる」ことが確認できたのは大きな成果です。 ◯ 睡眠の質（2.51→2.36）・起床時コンディション（2.58→2.36）・平均運動後疲労（3.56→3.38）がそろって改善。8/14〜8/17は180分練習を2回含む4連続練習でも瞬発力・持久力4を維持できていました。 ◯ 7/24からウエイトトレーニングを導入し「扱う重量に慣れてきた」(7/27)、8/22 日福記録会では「1発1発の伸びは大きかった」と記録。筋力づくりの手応えが出始めている可能性があります。
B36: ② 気になった点（早めに手を打ちたいこと）
B37: ◯ 暑さ・湿度が今期間いちばんの課題。メモに「暑い・湿度・熱中症」とある7日は、運動後疲労4.4（その他の日3.2）、瞬発力2.6（同3.5）、持久力2.3（同3.4）とはっきり低下しています。9/17は「熱中症になったかも」、9/24も「暑かったせいか」で瞬発力・持久力ともに1。逆に9/21は「涼しかったせいか？」で疲労2と好調でした。暑熱対策（練習前の身体冷却、冷たいドリンク、アイスタオル・霧吹きなど）を本人と一緒に決めておきたいところです。 ◯ 長い練習の日ほど補食が抜けています。180分以上の練習日の補食は11日中3日（27%）で、60〜120分の日（80%）と大きな差。特に9/12〜9/19は180分練習が6回・週960分と期間最大の負荷だったのに、補食は7日中1日のみ。この週に疲労5が2回（9/17・9/19）、熱中症疑いも重なっています。 ◯ 平均睡眠時間が7.16h→6.72hに減少し、7時間未満の日が14日（前回8日）。8/2〜8/12（移動・遠征と思われる期間）は5h以下が続き、8/11は睡眠3h・睡眠の質5・起床時CD4。睡眠6h未満の日は起床時コンディションが3.2（6h以上は2.3）と悪くなっています。遠征時の睡眠の確保（移動中の仮眠、アイマスク・耳栓など）を検討されてはいかがでしょうか。 ◯ 体重は平均61.3→62.5kg（+1.2kg）、変動幅2.4kg（目安1.5kg以内）。ウエイト導入による筋量アップであれば良い変化ですが、9月は日ごとに±0.5〜1kg上下しているため、測定タイミング（起床・排尿後など）を揃えると変化が読み取りやすくなります。増量・維持どちらを目指すかもコーチと共有しておくと安心です。
B38: ③ 次の大会までの小さな目標（1つだけ）
B39: ◯ 「長い練習（120分以上）の日こそ補食」：練習バッグにおにぎり＋ゼリー飲料（または牛乳・豆乳）を必ず入れておき、練習後30分以内に摂る。暑い日は練習前〜練習中に冷たいスポーツドリンクを飲み、水分・糖質補給と体の冷却を同時に行う。
B41: ■ 選手から（自己振り返り欄）
B42: Q1. 今期間で「調子がよかった」と感じた日と、その理由
B43: （選手記入欄）
B44: Q2. 逆に「うまくいかなかった」日と、思い当たる原因（暑さ・睡眠・食事など）
... B47: （選手記入欄）

Sheet ② 日次統合データ
A1: 日次統合データ（全項目を1行で確認） 緑＝良好／オレンジ・赤＝注意／グレー＝休養日
A3: 日付 | B3: 種目 | C3: 練習時間(分) | D3: RPE | E3: 瞬発力 | F3: 持久力 | G3: 運動後疲労 | H3: 体重(kg) | I3: 起床時CD | J3: 睡眠の質 | K3: 睡眠時間(h) | L3: 補食 | M3: 栄養Bal | N3: 水分(ml) | O3: メモ
A4: 46225 | B4: 実践トレーニング | C4: 60 | D4: 7 | E4: 4 | F4: 4 | G4: 3 | H4: 61.4 | I4: 1 | J4: 1 | K4: 8 | L4: はい | M4: 3 | N4: 1000
A5: 46226 | B5: 実践トレーニング | C5: 60 | D5: 6 | E5: 2 | F5: 2 | G5: 4 | H5: 61.3 | I5: 1 | J5: 1 | K5: 7 | L5: いいえ | M5: 3 | N5: 1000 | O5: 久しぶりの外でのトレーニング 暑すぎてパフォーマンス上がらなかった
A6: 46227 | B6: 実践＋ウエイト | C6: 120 | D6: 8 | E6: 4 | F6: 4 | G6: 4 | H6: 61.8 | I6: 2 | J6: 3 | K6: 7 | L6: はい | M6: 2 | N6: 1000 | O6: [ウエイト] 暑かった
A7: 46228 | B7: 実践トレーニング | C7: 60 | D7: 6 | E7: 4 | F7: 3 | G7: 3 | H7: 61.3 | I7: 3 | J7: 2 | K7: 7 | L7: いいえ | M7: 3 | N7: 1000
A8: 46229 | B8: 実践トレーニング | C8: 60 | D8: 6 | E8: 3 | F8: 4 | G8: 3 | H8: 61.1 | I8: 2 | J8: 3 | K8: 8 | L8: はい | M8: 2 | N8: 1000
A9: 46230 | B9: 実践＋ウエイト | C9: 120 | D9: 8 | E9: 2 | F9: 2 | G9: 4 | H9: 61.8 | I9: 1 | J9: 3 | K9: 7 | L9: はい | M9: 3 | N9: 1000 | O9: [実践] 久しぶりの実走 / [ウエイト] 扱う重量に慣れてきた
A10: 46231 | B10: 実践トレーニング | C10: 60 | D10: 6 | E10: 4 | F10: 4 | G10: 3 | H10: 61.7 | I10: 2 | J10: 2 | K10: 7 | L10: はい | M10: 3 | N10: 1000
A11: 46232 | B11: 実践トレーニング | C11: 60 | D11: 5 | E11: 4 | F11: 4 | G11: 3 | H11: 62.4 | I11: 3 | J11: 2 | K11: 7 | L11: はい | M11: 3 | N11: 1000
A12: 46233 | B12: 実践トレーニング | C12: 120 | D12: 7 | E12: 3 | F12: 4 | G12: 3 | H12: 62 | I12: 3 | J12: 1 | K12: 7 | L12: はい | M12: 4 | N12: 1000
A13: 46234 | B13: 実践トレーニング | C13: 60 | D13: 7 | E13: 2 | F13: 3 | G13: 4 | H13: 62.1 | I13: 2 | J13: 1 | K13: 6 | L13: いいえ | M13: 2 | N13: 1000 | O13: 湿度のせいかな
A14: 46235 | B14: 実践トレーニング | C14: 120 | D14: 6 | E14: 4 | F14: 4 | G14: 3 | H14: 61.4 | I14: 2 | J14: 2 | K14: 7 | L14: はい | M14: 2 | N14: 1000
A15: 46236 | B15: 実践トレーニング | C15: 60 | D15: 7 | E15: 4 | F15: 4 | G15: 3 | H15: 62.2 | I15: 2 | J15: 2 | K15: 5 | L15: はい | M15: 3 | N15: 1000
A16: 46238 | B16: 実践トレーニング | C16: 120 | D16: 7 | E16: 2 | F16: 2 | G16: 4 | H16: 62.4 | I16: 4 | J16: 4 | K16: 5 | L16: はい | M16: 2 | N16: 1500 | O16: 移動疲れかも
A17: 46245 | B17: 実践トレーニング | C17: 60 | D17: 3 | E17: 4 | F17: 4 | G17: 2 | H17: 62.4 | I17: 4 | J17: 5 | K17: 3 | L17: はい | M17: 4 | N17: 1000
A18: 46246 | B18: 休養日 | C18: 0 | H18: 63 | I18: 3 | J18: 3 | K18: 5 | L18: いいえ | M18: 2 | N18: 1000
A19: 46247 | B19: 休養日 | C19: 0 | H19: 62.2 | I19: 3 | J19: 3 | K19: 7 | L19: いいえ | M19: 4 | N19: 500
A20: 46248 | B20: 実践トレーニング | C20: 180 | D20: 6 | E20: 4 | F20: 4 | G20: 3 | H20: 62.7 | I20: 2 | J20: 2 | K20: 7 | L20: いいえ | M20: 2 | N20: 1000
A21: 46249 | B21: 実践トレーニング | C21: 60 | D21: 5 | E21: 4 | F21: 4 | G21: 3 | H21: 62 | I21: 2 | J21: 2 | K21: 7 | L21: はい | M21: 3 | N21: 1000
A22: 46250 | B22: 実践トレーニング | C22: 180 | D22: 7 | E22: 4 | F22: 4 | G22: 3 | H22: 62.2 | I22: 3 | J22: 3 | K22: 7 | L22: いいえ | M22: 4 | N22: 1000
A23: 46251 | B23: 実践トレーニング | C23: 120 | D23: 7 | E23: 4 | F23: 4 | G23: 3 | H23: 62.9 | I23: 2 | J23: 2 | K23: 7 | L23: はい | M23: 2 | N23: 1000
A24: 46252 | B24: 実践トレーニング | C24: 90 | D24: 7 | E24: 3 | F24: 4 | G24: 4 | I24: 2 | J24: 2 | K24: 7 | L24: いいえ | M24: 3 | N24: 1000
A25: 46254 | B25: 実践トレーニング | C25: 120 | D25: 7 | E25: 4 | F25: 3 | G25: 4 | H25: 62.4 | I25: 2 | J25: 1 | K25: 7 | L25: はい | M25: 1 | N25: 1000 | O25: 暑かった
A26: 46256 | B26: 実践トレーニング | C26: 60 | D26: 10 | E26: 3 | F26: 3 | G26: 3 | H26: 62.8 | I26: 2 | J26: 3 | K26: 6 | L26: はい | M26: 4 | N26: 1000 | O26: 日福記録会 動きが遅くピッチが出なかったけど1発1発の伸びは大きかった
A27: 46257 | B27: 休養日 | C27: 0 | H27: 62.2 | I27: 3 | J27: 4 | K27: 5 | L27: いいえ | M27: 4 | N27: 500
A28: 46258 | B28: 休養日 | C28: 0 | H28: 63.2 | I28: 2 | J28: 2 | K28: 6 | L28: いいえ | M28: 3 | N28: 1000
A29: 46259 | B29: 実践トレーニング | C29: 180 | D29: 7 | E29: 4 | F29: 3 | G29: 4 | H29: 63.4 | I29: 2 | J29: 2 | K29: 7 | L29: はい | M29: 3 | N29: 1000
A30: 46260 | B30: 実践トレーニング | C30: 120 | D30: 6 | E30: 4 | F30: 3 | G30: 3 | H30: 63.2 | I30: 2 | J30: 1 | K30: 7 | L30: はい | M30: 3 | N30: 1000
A31: 46261 | B31: 実践トレーニング | C31: 120 | D31: 7 | E31: 4 | F31: 3 | G31: 3 | H31: 63.4 | I31: 2 | J31: 3 | K31: 7 | L31: はい | M31: 3 | N31: 500
A32: 46262 | B32: 実践トレーニング | C32: 60 | D32: 5 | E32: 4 | F32: 4 | G32: 2 | H32: 62.8 | I32: 2 | J32: 1 | K32: 7 | L32: いいえ | M32: 3 | N32: 1000
A33: 46263 | B33: 実践トレーニング | C33: 60 | D33: 5 | E33: 3 | F33: 3 | G33: 3 | H33: 62.8 | I33: 2 | J33: 2 | K33: 7 | L33: はい | M33: 3 | N33: 1000
A34: 46264 | B34: 実践トレーニング | C34: 60 | D34: 7 | E34: 4 | F34: 4 | G34: 3 | H34: 62.6 | I34: 3 | J34: 3 | K34: 7 | L34: はい | M34: 3 | N34: 1000
A35: 46265 | B35: 実践トレーニング | C35: 60 | D35: 6 | E35: 4 | F35: 4 | G35: 3 | H35: 62.9 | I35: 3 | J35: 1 | K35: 7 | L35: はい | M35: 2 | N35: 1000
A36: 46266 | B36: 実践トレーニング | C36: 60 | D36: 5 | E36: 3 | F36: 4 | G36: 3 | H36: 63 | I36: 2 | J36: 2 | K36: 7 | L36: はい | M36: 2 | N36: 500
A37: 46267 | B37: 実践トレーニング | C37: 60 | D37: 5 | E37: 4 | F37: 4 | G37: 3 | H37: 62.4 | I37: 3 | J37: 2 | K37: 7 | L37: はい | M37: 3 | N37: 1000
A38: 46268 | B38: 実践＋ウエイト | C38: 120 | D38: 8 | E38: 3 | F38: 3 | G38: 4 | H38: 63 | I38: 2 | J38: 2 | K38: 7 | L38: はい | M38: 3 | N38: 1000
A39: 46269 | B39: 実践トレーニング | C39: 120 | D39: 8 | E39: 4 | F39: 3 | G39: 3 | H39: 62.1 | I39: 3 | J39: 3 | K39: 7 | L39: はい | M39: 3 | N39: 1000
A40: 46270 | B40: 実践トレーニング | C40: 120 | D40: 6 | E40: 3 | F40: 2 | G40: 3 | H40: 62.8 | I40: 3 | J40: 3 | K40: 6 | L40: はい | M40: 3 | N40: 1000
A41: 46271 | B41: 実践トレーニング | C41: 60 | D41: 5 | E41: 3 | F41: 2 | G41: 4 | H41: 62.6 | I41: 2 | J41: 2 | K41: 7 | L41: はい | M41: 3 | N41: 1000
...

Sheet ③ 食事バランス
A1: タンパク源バランス（色がついている＝摂取あり）
A3: ◎ 「魚・肉・豆・卵」がバランスよく揃うと回復が早まります。空白マスが多い列は意識的に増やしましょう。
A5: 日付 | B5: 昼:魚 | C5: 昼:肉 | D5: 昼:豆 | E5: 昼:卵 | F5: 夕:魚 | G5: 夕:肉 | H5: 夕:豆 | I5: 夕:卵 | J5: 種類数(昼+夕) | K5: 補食
A6: 46225 | E6: ○ | G6: ○ | I6: ○ | J6: =COUNTIF(B6:I6,"○") -> 3 | K6: はい
A7: 46226 | C7: ○ | E7: ○ | F7: ○ | G7: ○ | I7: ○ | J7: =COUNTIF(B7:I7,"○") -> 5 | K7: いいえ
A8: 46227 | E8: ○ | G8: ○ | J8: =COUNTIF(B8:I8,"○") -> 2 | K8: はい
A9: 46228 | C9: ○ | G9: ○ | I9: ○ | J9: =COUNTIF(B9:I9,"○") -> 3 | K9: いいえ
A10: 46229 | B10: ○ | E10: ○ | G10: ○ | I10: ○ | J10: =COUNTIF(B10:I10,"○") -> 4 | K10: はい
A11: 46230 | G11: ○ | I11: ○ | J11: =COUNTIF(B11:I11,"○") -> 2 | K11: はい
A12: 46231 | C12: ○ | G12: ○ | I12: ○ | J12: =COUNTIF(B12:I12,"○") -> 3 | K12: はい
A13: 46232 | C13: ○ | G13: ○ | I13: ○ | J13: =COUNTIF(B13:I13,"○") -> 3 | K13: はい
A14: 46233 | C14: ○ | G14: ○ | J14: =COUNTIF(B14:I14,"○") -> 2 | K14: はい
A15: 46234 | C15: ○ | F15: ○ | G15: ○ | H15: ○ | J15: =COUNTIF(B15:I15,"○") -> 4 | K15: いいえ
A16: 46235 | C16: ○ | G16: ○ | H16: ○ | I16: ○ | J16: =COUNTIF(B16:I16,"○") -> 4 | K16: はい
A17: 46236 | C17: ○ | G17: ○ | I17: ○ | J17: =COUNTIF(B17:I17,"○") -> 3 | K17: はい
A18: 46238 | C18: ○ | D18: ○ | E18: ○ | G18: ○ | I18: ○ | J18: =COUNTIF(B18:I18,"○") -> 5 | K18: はい
A19: 46245 | C19: ○ | G19: ○ | H19: ○ | I19: ○ | J19: =COUNTIF(B19:I19,"○") -> 4 | K19: はい
A20: 46246 | E20: ○ | F20: ○ | H20: ○ | I20: ○ | J20: =COUNTIF(B20:I20,"○") -> 4 | K20: いいえ
A21: 46247 | E21: ○ | G21: ○ | I21: ○ | J21: =COUNTIF(B21:I21,"○") -> 3 | K21: いいえ
A22: 46248 | E22: ○ | F22: ○ | G22: ○ | H22: ○ | I22: ○ | J22: =COUNTIF(B22:I22,"○") -> 5 | K22: いいえ
A23: 46249 | C23: ○ | F23: ○ | G23: ○ | H23: ○ | J23: =COUNTIF(B23:I23,"○") -> 4 | K23: はい
A24: 46250 | I24: ○ | J24: =COUNTIF(B24:I24,"○") -> 1 | K24: いいえ
A25: 46251 | C25: ○ | F25: ○ | G25: ○ | H25: ○ | J25: =COUNTIF(B25:I25,"○") -> 4 | K25: はい
A26: 46252 | G26: ○ | J26: =COUNTIF(B26:I26,"○") -> 1 | K26: いいえ
A27: 46254 | C27: ○ | G27: ○ | H27: ○ | I27: ○ | J27: =COUNTIF(B27:I27,"○") -> 4 | K27: はい
A28: 46256 | G28: ○ | J28: =COUNTIF(B28:I28,"○") -> 1 | K28: はい
A29: 46257 | G29: ○ | H29: ○ | I29: ○ | J29: =COUNTIF(B29:I29,"○") -> 3 | K29: いいえ
A30: 46258 | C30: ○ | G30: ○ | J30: =COUNTIF(B30:I30,"○") -> 2 | K30: いいえ
A31: 46259 | C31: ○ | F31: ○ | J31: =COUNTIF(B31:I31,"○") -> 2 | K31: はい
A32: 46260 | F32: ○ | G32: ○ | H32: ○ | I32: ○ | J32: =COUNTIF(B32:I32,"○") -> 4 | K32: はい
A33: 46261 | F33: ○ | G33: ○ | H33: ○ | I33: ○ | J33: =COUNTIF(B33:I33,"○") -> 4 | K33: はい
A34: 46262 | C34: ○ | G34: ○ | H34: ○ | J34: =COUNTIF(B34:I34,"○") -> 3 | K34: いいえ
A35: 46263 | C35: ○ | F35: ○ | G35: ○ | J35: =COUNTIF(B35:I35,"○") -> 3 | K35: はい
A36: 46264 | E36: ○ | F36: ○ | H36: ○ | J36: =COUNTIF(B36:I36,"○") -> 3 | K36: はい
A37: 46265 | C37: ○ | G37: ○ | H37: ○ | J37: =COUNTIF(B37:I37,"○") -> 3 | K37: はい
A38: 46266 | C38: ○ | E38: ○ | G38: ○ | J38: =COUNTIF(B38:I38,"○") -> 3 | K38: はい
A39: 46267 | F39: ○ | G39: ○ | H39: ○ | J39: =COUNTIF(B39:I39,"○") -> 3 | K39: はい
A40: 46268 | C40: ○ | G40: ○ | H40: ○ | I40: ○ | J40: =COUNTIF(B40:I40,"○") -> 4 | K40: はい
A41: 46269 | F41: ○ | G41: ○ | H41: ○ | J41: =COUNTIF(B41:I41,"○") -> 3 | K41: はい
A42: 46270 | E42: ○ | G42: ○ | J42: =COUNTIF(B42:I42,"○") -> 2 | K42: はい
...

Sheet ④ トレンドグラフ
A1: トレンドグラフ（時系列）
A3: グラフ元データは「② 日次統合データ」を参照しています。空白期間（8/5〜8/10）は記録なし。
A5: ■ 週間トレーニング時間（月曜始まり）
A6: 週の開始(月) | B6: 練習時間(分) | C6: 練習日数 | D6: 平均RPE | E6: 平均運動後疲労 | F6: 補食「はい」日数
A7: 46223 | B7: =SUMIFS('② 日次統合データ'!$C$4:$C$67,'② 日次統合データ'!$A$4:$A$67,">="&A7,'② 日次統合データ'!$A$4:$A$67,"<"&A7+7) -> 360 | C7: =COUNTIFS('② 日次統合データ'!$A$4:$A$67,">="&A7,'② 日次統合データ'!$A$4:$A$67,"<"&A7+7,'② 日次統合データ'!$B$4:$B$67,"<>休養日") -> 5 | D7: =IFERROR(AVERAGEIFS('② 日次統合データ'!$D$4:$D$67,'② 日次統合データ'!$A$4:$A$67,">="&A7,'② 日次統合データ'!$A$4:$A$67,"<"&A7+7),"-") -> 6.6 | E7: =IFERROR(AVERAGEIFS('② 日次統合データ'!$G$4:$G$67,'② 日次統合データ'!$A$4:$A$67,">="&A7,'② 日次統合データ'!$A$4:$A$67,"<"&A7+7),"-") -> 3.4 | F7: =COUNTIFS('② 日次統合データ'!$A$4:$A$67,">="&A7,'② 日次統合データ'!$A$4:$A$67,"<"&A7+7,'② 日次統合データ'!$L$4:$L$67,"はい",'② 日次統合データ'!$B$4:$B$67,"<>休養日") -> 3
A8: 46230 | B8: =SUMIFS('② 日次統合データ'!$C$4:$C$67,'② 日次統合データ'!$A$4:$A$67,">="&A8,'② 日次統合データ'!$A$4:$A$67,"<"&A8+7) -> 600 | C8: =COUNTIFS('② 日次統合データ'!$A$4:$A$67,">="&A8,'② 日次統合データ'!$A$4:$A$67,"<"&A8+7,'② 日次統合データ'!$B$4:$B$67,"<>休養日") -> 7 | D8: =IFERROR(AVERAGEIFS('② 日次統合データ'!$D$4:$D$67,'② 日次統合データ'!$A$4:$A$67,">="&A8,'② 日次統合データ'!$A$4:$A$67,"<"&A8+7),"-") -> 6.5714286 | E8: =IFERROR(AVERAGEIFS('② 日次統合データ'!$G$4:$G$67,'② 日次統合データ'!$A$4:$A$67,">="&A8,'② 日次統合データ'!$A$4:$A$67,"<"&A8+7),"-") -> 3.2857143 | F8: =COUNTIFS('② 日次統合データ'!$A$4:$A$67,">="&A8,'② 日次統合データ'!$A$4:$A$67,"<"&A8+7,'② 日次統合データ'!$L$4:$L$67,"はい",'② 日次統合データ'!$B$4:$B$67,"<>休養日") -> 6
A9: 46237 | B9: =SUMIFS('② 日次統合データ'!$C$4:$C$67,'② 日次統合データ'!$A$4:$A$67,">="&A9,'② 日次統合データ'!$A$4:$A$67,"<"&A9+7) -> 120 | C9: =COUNTIFS('② 日次統合データ'!$A$4:$A$67,">="&A9,'② 日次統合データ'!$A$4:$A$67,"<"&A9+7,'② 日次統合データ'!$B$4:$B$67,"<>休養日") -> 1 | D9: =IFERROR(AVERAGEIFS('② 日次統合データ'!$D$4:$D$67,'② 日次統合データ'!$A$4:$A$67,">="&A9,'② 日次統合データ'!$A$4:$A$67,"<"&A9+7),"-") -> 7 | E9: =IFERROR(AVERAGEIFS('② 日次統合データ'!$G$4:$G$67,'② 日次統合データ'!$A$4:$A$67,">="&A9,'② 日次統合データ'!$A$4:$A$67,"<"&A9+7),"-") -> 4 | F9: =COUNTIFS('② 日次統合データ'!$A$4:$A$67,">="&A9,'② 日次統合データ'!$A$4:$A$67,"<"&A9+7,'② 日次統合データ'!$L$4:$L$67,"はい",'② 日次統合データ'!$B$4:$B$67,"<>休養日") -> 1
A10: 46244 | B10: =SUMIFS('② 日次統合データ'!$C$4:$C$67,'② 日次統合データ'!$A$4:$A$67,">="&A10,'② 日次統合データ'!$A$4:$A$67,"<"&A10+7) -> 480 | C10: =COUNTIFS('② 日次統合データ'!$A$4:$A$67,">="&A10,'② 日次統合データ'!$A$4:$A$67,"<"&A10+7,'② 日次統合データ'!$B$4:$B$67,"<>休養日") -> 4 | D10: =IFERROR(AVERAGEIFS('② 日次統合データ'!$D$4:$D$67,'② 日次統合データ'!$A$4:$A$67,">="&A10,'② 日次統合データ'!$A$4:$A$67,"<"&A10+7),"-") -> 5.25 | E10: =IFERROR(AVERAGEIFS('② 日次統合データ'!$G$4:$G$67,'② 日次統合データ'!$A$4:$A$67,">="&A10,'② 日次統合データ'!$A$4:$A$67,"<"&A10+7),"-") -> 2.75 | F10: =COUNTIFS('② 日次統合データ'!$A$4:$A$67,">="&A10,'② 日次統合データ'!$A$4:$A$67,"<"&A10+7,'② 日次統合データ'!$L$4:$L$67,"はい",'② 日次統合データ'!$B$4:$B$67,"<>休養日") -> 2
A11: 46251 | B11: =SUMIFS('② 日次統合データ'!$C$4:$C$67,'② 日次統合データ'!$A$4:$A$67,">="&A11,'② 日次統合データ'!$A$4:$A$67,"<"&A11+7) -> 390 | C11: =COUNTIFS('② 日次統合データ'!$A$4:$A$67,">="&A11,'② 日次統合データ'!$A$4:$A$67,"<"&A11+7,'② 日次統合データ'!$B$4:$B$67,"<>休養日") -> 4 | D11: =IFERROR(AVERAGEIFS('② 日次統合データ'!$D$4:$D$67,'② 日次統合データ'!$A$4:$A$67,">="&A11,'② 日次統合データ'!$A$4:$A$67,"<"&A11+7),"-") -> 7.75 | E11: =IFERROR(AVERAGEIFS('② 日次統合データ'!$G$4:$G$67,'② 日次統合データ'!$A$4:$A$67,">="&A11,'② 日次統合データ'!$A$4:$A$67,"<"&A11+7),"-") -> 3.5 | F11: =COUNTIFS('② 日次統合データ'!$A$4:$A$67,">="&A11,'② 日次統合データ'!$A$4:$A$67,"<"&A11+7,'② 日次統合データ'!$L$4:$L$67,"はい",'② 日次統合データ'!$B$4:$B$67,"<>休養日") -> 3
A12: 46258 | B12: =SUMIFS('② 日次統合データ'!$C$4:$C$67,'② 日次統合データ'!$A$4:$A$67,">="&A12,'② 日次統合データ'!$A$4:$A$67,"<"&A12+7) -> 600 | C12: =COUNTIFS('② 日次統合データ'!$A$4:$A$67,">="&A12,'② 日次統合データ'!$A$4:$A$67,"<"&A12+7,'② 日次統合データ'!$B$4:$B$67,"<>休養日") -> 6 | D12: =IFERROR(AVERAGEIFS('② 日次統合データ'!$D$4:$D$67,'② 日次統合データ'!$A$4:$A$67,">="&A12,'② 日次統合データ'!$A$4:$A$67,"<"&A12+7),"-") -> 6.1666667 | E12: =IFERROR(AVERAGEIFS('② 日次統合データ'!$G$4:$G$67,'② 日次統合データ'!$A$4:$A$67,">="&A12,'② 日次統合データ'!$A$4:$A$67,"<"&A12+7),"-") -> 3 | F12: =COUNTIFS('② 日次統合データ'!$A$4:$A$67,">="&A12,'② 日次統合データ'!$A$4:$A$67,"<"&A12+7,'② 日次統合データ'!$L$4:$L$67,"はい",'② 日次統合データ'!$B$4:$B$67,"<>休養日") -> 5
A13: 46265 | B13: =SUMIFS('② 日次統合データ'!$C$4:$C$67,'② 日次統合データ'!$A$4:$A$67,">="&A13,'② 日次統合データ'!$A$4:$A$67,"<"&A13+7) -> 600 | C13: =COUNTIFS('② 日次統合データ'!$A$4:$A$67,">="&A13,'② 日次統合データ'!$A$4:$A$67,"<"&A13+7,'② 日次統合データ'!$B$4:$B$67,"<>休養日") -> 7 | D13: =IFERROR(AVERAGEIFS('② 日次統合データ'!$D$4:$D$67,'② 日次統合データ'!$A$4:$A$67,">="&A13,'② 日次統合データ'!$A$4:$A$67,"<"&A13+7),"-") -> 6.1428571 | E13: =IFERROR(AVERAGEIFS('② 日次統合データ'!$G$4:$G$67,'② 日次統合データ'!$A$4:$A$67,">="&A13,'② 日次統合データ'!$A$4:$A$67,"<"&A13+7),"-") -> 3.2857143 | F13: =COUNTIFS('② 日次統合データ'!$A$4:$A$67,">="&A13,'② 日次統合データ'!$A$4:$A$67,"<"&A13+7,'② 日次統合データ'!$L$4:$L$67,"はい",'② 日次統合データ'!$B$4:$B$67,"<>休養日") -> 7
A14: 46272 | B14: =SUMIFS('② 日次統合データ'!$C$4:$C$67,'② 日次統合データ'!$A$4:$A$67,">="&A14,'② 日次統合データ'!$A$4:$A$67,"<"&A14+7) -> 700 | C14: =COUNTIFS('② 日次統合データ'!$A$4:$A$67,">="&A14,'② 日次統合データ'!$A$4:$A$67,"<"&A14+7,'② 日次統合データ'!$B$4:$B$67,"<>休養日") -> 5 | D14: =IFERROR(AVERAGEIFS('② 日次統合データ'!$D$4:$D$67,'② 日次統合データ'!$A$4:$A$67,">="&A14,'② 日次統合データ'!$A$4:$A$67,"<"&A14+7),"-") -> 7 | E14: =IFERROR(AVERAGEIFS('② 日次統合データ'!$G$4:$G$67,'② 日次統合データ'!$A$4:$A$67,">="&A14,'② 日次統合データ'!$A$4:$A$67,"<"&A14+7),"-") -> 4 | F14: =COUNTIFS('② 日次統合データ'!$A$4:$A$67,">="&A14,'② 日次統合データ'!$A$4:$A$67,"<"&A14+7,'② 日次統合データ'!$L$4:$L$67,"はい",'② 日次統合データ'!$B$4:$B$67,"<>休養日") -> 4
A15: 46279 | B15: =SUMIFS('② 日次統合データ'!$C$4:$C$67,'② 日次統合データ'!$A$4:$A$67,">="&A15,'② 日次統合データ'!$A$4:$A$67,"<"&A15+7) -> 960 | C15: =COUNTIFS('② 日次統合データ'!$A$4:$A$67,">="&A15,'② 日次統合データ'!$A$4:$A$67,"<"&A15+7,'② 日次統合データ'!$B$4:$B$67,"<>休養日") -> 6 | D15: =IFERROR(AVERAGEIFS('② 日次統合データ'!$D$4:$D$67,'② 日次統合データ'!$A$4:$A$67,">="&A15,'② 日次統合データ'!$A$4:$A$67,"<"&A15+7),"-") -> 7.1666667 | E15: =IFERROR(AVERAGEIFS('② 日次統合データ'!$G$4:$G$67,'② 日次統合データ'!$A$4:$A$67,">="&A15,'② 日次統合データ'!$A$4:$A$67,"<"&A15+7),"-") -> 4 | F15: =COUNTIFS('② 日次統合データ'!$A$4:$A$67,">="&A15,'② 日次統合データ'!$A$4:$A$67,"<"&A15+7,'② 日次統合データ'!$L$4:$L$67,"はい",'② 日次統合データ'!$B$4:$B$67,"<>休養日") -> 1
A16: 46286 | B16: =SUMIFS('② 日次統合データ'!$C$4:$C$67,'② 日次統合データ'!$A$4:$A$67,">="&A16,'② 日次統合データ'!$A$4:$A$67,"<"&A16+7) -> 420 | C16: =COUNTIFS('② 日次統合データ'!$A$4:$A$67,">="&A16,'② 日次統合データ'!$A$4:$A$67,"<"&A16+7,'② 日次統合データ'!$B$4:$B$67,"<>休養日") -> 5 | D16: =IFERROR(AVERAGEIFS('② 日次統合データ'!$D$4:$D$67,'② 日次統合データ'!$A$4:$A$67,">="&A16,'② 日次統合データ'!$A$4:$A$67,"<"&A16+7),"-") -> 6.4 | E16: =IFERROR(AVERAGEIFS('② 日次統合データ'!$G$4:$G$67,'② 日次統合データ'!$A$4:$A$67,">="&A16,'② 日次統合データ'!$A$4:$A$67,"<"&A16+7),"-") -> 3.2 | F16: =COUNTIFS('② 日次統合データ'!$A$4:$A$67,">="&A16,'② 日次統合データ'!$A$4:$A$67,"<"&A16+7,'② 日次統合データ'!$L$4:$L$67,"はい",'② 日次統合データ'!$B$4:$B$67,"<>休養日") -> 3
A17: 46293 | B17: =SUMIFS('② 日次統合データ'!$C$4:$C$67,'② 日次統合データ'!$A$4:$A$67,">="&A17,'② 日次統合データ'!$A$4:$A$67,"<"&A17+7) -> 240 | C17: =COUNTIFS('② 日次統合データ'!$A$4:$A$67,">="&A17,'② 日次統合データ'!$A$4:$A$67,"<"&A17+7,'② 日次統合データ'!$B$4:$B$67,"<>休養日") -> 2 | D17: =IFERROR(AVERAGEIFS('② 日次統合データ'!$D$4:$D$67,'② 日次統合データ'!$A$4:$A$67,">="&A17,'② 日次統合データ'!$A$4:$A$67,"<"&A17+7),"-") -> 6 | E17: =IFERROR(AVERAGEIFS('② 日次統合データ'!$G$4:$G$67,'② 日次統合データ'!$A$4:$A$67,">="&A17,'② 日次統合データ'!$A$4:$A$67,"<"&A17+7),"-") -> 3 | F17: =COUNTIFS('② 日次統合データ'!$A$4:$A$67,">="&A17,'② 日次統合データ'!$A$4:$A$67,"<"&A17+7,'② 日次統合データ'!$L$4:$L$67,"はい",'② 日次統合データ'!$B$4:$B$67,"<>休養日") -> 1
A18: ※ 8/3〜8/9週は記録が8/4のみ。9/14〜9/20週が期間最多（960分）で、この週は補食が1日のみ。

Sheet ⑤ 関連性ヒント
A1: ■ Section A：既存の関連性ヒント（前回と同じ5項目を今期間データで再計算）
A2: 観点 | B2: 条件A（低/良） | C2: n | D2: 条件B（高/悪） | E2: n | F2: 差(B-A) | G2: 注目度 | H2: 前期間の差 | I2: 前回との比較
A3: 補食(はい/いいえ) → 翌日 運動後疲労 | B3: はい: 3.43 | C3: 30 | D3: いいえ: 3.40 | E3: 20 | F3: -0.03 | G3: − | H3: -0.17 | I3: 変わらず関連なし
A4: 睡眠時間(≥7h / <7h) → 同日 RPE | B4: ≥7h: 6.56 | C4: 41 | D4: <7h: 6.45 | E4: 11 | F4: -0.11 | G4: − | H4: 1.03 | I4: 今期は差が縮小
A5: 睡眠の質(良≤2 / 悪≥3) → 同日 運動後疲労 | B5: ≤2(良): 3.31 | C5: 32 | D5: ≥3(悪): 3.50 | E5: 20 | F5: 0.19 | G5: − | H5: -0.06 | I5: 変わらず関連なし
A6: 水分摂取量(≥1000ml / <1000ml) → 同日 運動後疲労 | B6: ≥1000ml: 3.44 | C6: 48 | D6: <1000ml: 2.75 | E6: 4 | F6: -0.69 | G6: ★要注目（n少） | H6: -0.52 | I6: 同じ傾向（再現）
A7: タンパク質合計種類数(1〜2種 / 3種以上) → 翌日 RPE | B7: 1〜2種: 6.33 | C7: 9 | D7: 3種以上: 6.66 | E7: 41 | F7: 0.33 | G7: 参考 | H7: -0.46 | I7: 逆の傾向
A9: ■ Section B：前回「新たに判明した関連性」4項目の再確認
A10: 観点 | B10: 条件A（低/良） | C10: n | D10: 条件B（高/悪） | E10: n | F10: 差(B-A) | G10: 注目度 | H10: 前期間の差 | I10: 前回との比較
A11: 睡眠の質(良好≤2 / 不良≥3) → 翌日 RPE | B11: 良好≤2: 6.75 | C11: 32 | D11: 不良≥3: 6.33 | E11: 18 | F11: -0.42 | G11: 参考 | H11: -0.75 | I11: 同じ傾向（再現）
A12: 栄養バランス(良好1〜2 / 不良3〜4) → 翌日 RPE | B12: 良好1〜2: 6.67 | C12: 15 | D12: 不良3〜4: 6.57 | E12: 35 | F12: -0.1 | G12: − | H12: 0.71 | I12: 今期は差が縮小
A13: 起床時コンディション(良好1〜2 / 不調4〜5) → 同日 運動後疲労 | B13: 良好1〜2: 3.44 | C13: 36 | D13: 不調4〜5: 3.00 | E13: 2 | F13: -0.44 | G13: 参考（n少） | H13: 0.78 | I13: 逆の傾向
A14: 起床時コンディション(良好1〜2 / 不調4〜5) → 同日 RPE | B14: 良好1〜2: 6.64 | C14: 36 | D14: 不調4〜5: 5.00 | E14: 2 | F14: -1.64 | G14: ★要注目（n少） | H14: -1.33 | I14: 同じ傾向（再現）
A16: ■ Section C：昼食・夕食タンパク質の詳細分析
A17: 平均タンパク質種類数 昼食: 0.91種（前回0.68） / 夕食: 2.28種（前回1.60）
A18: 昼食タンパク質との関連
A19: 観点 | B19: 条件A（低/良） | C19: n | D19: 条件B（高/悪） | E19: n | F19: 差(B-A) | G19: 注目度 | H19: 前期間の差 | I19: 前回との比較
A20: 昼食タンパク質種類数(0種 / 1種以上) → 翌日 RPE | B20: 0種: 6.69 | C20: 13 | D20: 1種以上: 6.57 | E20: 37 | F20: -0.12 | G20: − | H20: -0.89 | I20: 今期は差が縮小
A21: 昼食タンパク質種類数(0種 / 1種以上) → 翌日 運動後疲労 | B21: 0種: 3.31 | C21: 13 | D21: 1種以上: 3.46 | E21: 37 | F21: 0.15 | G21: − | H21: -0.24 | I21: 変わらず関連なし
A23: 夕食タンパク質との関連
A24: 観点 | B24: 条件A（低/良） | C24: n | D24: 条件B（高/悪） | E24: n | F24: 差(B-A) | G24: 注目度 | H24: 前期間の差 | I24: 前回との比較
A25: 夕食タンパク質種類数(1〜2種 / 3種以上) → 翌日 RPE | B25: 1〜2種: 6.39 | C25: 28 | D25: 3種以上: 6.86 | E25: 22 | F25: 0.47 | G25: 参考 | H25: -0.52 | I25: 逆の傾向
A26: 夕食タンパク質種類数(1〜2種 / 3種以上) → 翌日 運動後疲労 | B26: 1〜2種: 3.50 | C26: 28 | D26: 3種以上: 3.32 | E26: 22 | F26: -0.18 | G26: − | H26: 0 | I26: 変わらず関連なし
A27: 夕食タンパク質種類数(1〜2種 / 3種以上) → 翌日 起床時コンディション | B27: 1〜2種: 2.40 | C27: 35 | D27: 3種以上: 2.30 | E27: 27 | F27: -0.1 | G27: − | H27: 0.08 | I27: 変わらず関連なし
A29: 食材別（夕食）との関連 → 翌日 RPE
A30: 観点 | B30: 条件A（低/良） | C30: n | D30: 条件B（高/悪） | E30: n | F30: 差(B-A) | G30: 注目度 | H30: 前期間の差 | I30: 前回との比較
A31: 夕食に魚(なし / あり) → 翌日 RPE | B31: なし: 6.57 | C31: 28 | D31: あり: 6.64 | E31: 22 | F31: 0.06 | G31: − | H31: -0.53 | I31: 今期は差が縮小
A32: 夕食に肉(なし / あり) → 翌日 RPE | B32: なし: 6.75 | C32: 4 | D32: あり: 6.59 | E32: 46 | F32: -0.16 | G32: − | H32: -0.12 | I32: 変わらず関連なし
A33: 夕食に豆(なし / あり) → 翌日 RPE | B33: なし: 6.47 | C33: 30 | D33: あり: 6.80 | E33: 20 | F33: 0.33 | G33: 参考 | H33: 0 | I33: 今期新たに差
A34: 夕食に卵(なし / あり) → 翌日 RPE | B34: なし: 6.48 | C34: 21 | D34: あり: 6.69 | E34: 29 | F34: 0.21 | G34: − | H34: -0.19 | I34: 変わらず関連なし
A36: ■ Section D：今期間の追加分析（暑さ・睡眠不足・長時間練習）
A37: 観点 | B37: 条件A（低/良） | C37: n | D37: 条件B（高/悪） | E37: n | F37: 差(B-A) | G37: 注目度 | H37: 前期間の差 | I37: 前回との比較
A38: 暑さ・湿度のメモ(なし / あり) → 同日 運動後疲労 | B38: なし: 3.22 | C38: 45 | D38: あり: 4.43 | E38: 7 | F38: 1.21 | G38: ★要注目 p=0.000 | H38: − | I38: （今期新規）
A39: 暑さ・湿度のメモ(なし / あり) → 同日 瞬発力 | B39: なし: 3.51 | C39: 45 | D39: あり: 2.57 | E39: 7 | F39: -0.94 | G39: ★要注目 | H39: − | I39: （今期新規）
A40: 暑さ・湿度のメモ(なし / あり) → 同日 持久力 | B40: なし: 3.38 | C40: 45 | D40: あり: 2.29 | E40: 7 | F40: -1.09 | G40: ★要注目 p=0.041 | H40: − | I40: （今期新規）
A41: 睡眠時間(≥6h / <6h) → 同日 起床時コンディション | B41: ≥6h: 2.28 | C41: 58 | D41: <6h: 3.17 | E41: 6 | F41: 0.89 | G41: ★要注目 p=0.033 | H41: − | I41: （今期新規）
A42: 練習120分以上の日の補食(はい / いいえ) → 翌日 起床時コンディション | B42: はい: 2.24 | C42: 17 | D42: いいえ: 2.56 | E42: 9 | F42: 0.32 | G42: 参考 | H42: − | I42: （今期新規）
A43: 練習時間(<180分 / ≥180分) → 翌日 運動後疲労 | B43: <180分: 3.43 | C43: 35 | D43: ≥180分: 3.38 | E43: 8 | F43: -0.05 | G43: − | H43: − | I43: （今期新規）
A44: 練習時間(<180分 / ≥180分) → その日の補食実施率 | B44: <180分: 80% | C44: 41 | D44: ≥180分: 27% | E44: 11 | F44: -53pt | G44: ★要注目 | H44: − | I44: （今期新規）
A46: ※ 差の絶対値 0.5以上→要注目（黄色）、0.3以上→参考（薄黄色）。どちらかの群のnが5未満は「（n少）」として参考扱い。
...

Sheet データ_主観的体調
A1: データ_主観的体調
A3: 日付 | B3: 起床時コンディション | C3: 睡眠の質 | D3: 睡眠時間
A4: 46225 | B4: 1 | C4: 1 | D4: 8
A5: 46226 | B5: 1 | C5: 1 | D5: 7
A6: 46227 | B6: 2 | C6: 3 | D6: 7
A7: 46228 | B7: 3 | C7: 2 | D7: 7
A8: 46229 | B8: 2 | C8: 3 | D8: 8
A9: 46230 | B9: 1 | C9: 3 | D9: 7
A10: 46231 | B10: 2 | C10: 2 | D10: 7
A11: 46232 | B11: 3 | C11: 2 | D11: 7
A12: 46233 | B12: 3 | C12: 1 | D12: 7
A13: 46234 | B13: 2 | C13: 1 | D13: 6
A14: 46235 | B14: 2 | C14: 2 | D14: 7
A15: 46236 | B15: 2 | C15: 2 | D15: 5
... A67: 46299 | B67: 3 | C67: 3 | D67: 7

Sheet データ_身体データ
A1: データ_身体データ
A3: 日付 | B3: 体重_kg
A4: 46225 | B4: 61.4
A5: 46226 | B5: 61.3
A6: 46227 | B6: 61.8
A7: 46228 | B7: 61.3
A8: 46229 | B8: 61.1
A9: 46230 | B9: 61.8
A10: 46231 | B10: 61.7
A11: 46232 | B11: 62.4
A12: 46233 | B12: 62
A13: 46234 | B13: 62.1
A14: 46235 | B14: 61.4
A15: 46236 | B15: 62.2
... A23: 46251 | B23: 62.9
A24: 46252
A25: 46254 | B25: 62.4
A26: 46256 | B26: 62.8
A27: 46257 | B27: 62.2
A28: 46258 | B28: 63.2
A29: 46259 | B29: 63.4
A30: 46260 | B30: 63.2
A31: 46261 | B31: 63.4
A32: 46262 | B32: 62.8
A33: 46263 | B33: 62.8
A34: 46264 | B34: 62.6
A35: 46265 | B35: 62.9
A36: 46266 | B36: 63
... A62: 46292 | B62: 62.4
A63: 46293
A64: 46294 | B64: 63.2
A65: 46295 | B65: 62.5
A66: 46297
A67: 46299 | B67: 61.9

Sheet データ_トレーニング
A1: データ_トレーニング
A3: 日付 | B3: 種目 | C3: 時間_分 | D3: RPE | E3: 爆発力 | F3: 持久力 | G3: 運動後疲労 | H3: メモ
A4: 46225 | B4: 実践トレーニング | C4: 60 | D4: 7 | E4: 4 | F4: 4 | G4: 3
A5: 46226 | B5: 実践トレーニング | C5: 60 | D5: 6 | E5: 2 | F5: 2 | G5: 4 | H5: 久しぶりの外でのトレーニング 暑すぎてパフォーマンス上がらなかった
A6: 46227 | B6: 実践トレーニング | C6: 60 | D6: 6 | E6: 4 | F6: 4 | G6: 2
A7: 46227 | B7: ウエイトトレーニング | C7: 60 | D7: 8 | E7: 4 | F7: 4 | G7: 4 | H7: 暑かった
A8: 46228 | B8: 実践トレーニング | C8: 60 | D8: 6 | E8: 4 | F8: 3 | G8: 3
A9: 46229 | B9: 実践トレーニング | C9: 60 | D9: 6 | E9: 3 | F9: 4 | G9: 3
A10: 46230 | B10: 実践トレーニング | C10: 60 | D10: 7 | E10: 2 | F10: 2 | G10: 4 | H10: 久しぶりの実走
A11: 46230 | B11: ウエイトトレーニング | C11: 60 | D11: 8 | E11: 4 | F11: 4 | G11: 3 | H11: 扱う重量に慣れてきた
A12: 46231 | B12: 実践トレーニング | C12: 60 | D12: 6 | E12: 4 | F12: 4 | G12: 3
A13: 46232 | B13: 実践トレーニング | C13: 60 | D13: 5 | E13: 4 | F13: 4 | G13: 3
A14: 46233 | B14: 実践トレーニング | C14: 120 | D14: 7 | E14: 3 | F14: 4 | G14: 3
A15: 46234 | B15: 実践トレーニング | C15: 60 | D15: 7 | E15: 2 | F15: 3 | G15: 4 | H15: 湿度のせいかな
A16: 46235 | B16: 実践トレーニング | C16: 120 | D16: 6 | E16: 4 | F16: 4 | G16: 3
A17: 46236 | B17: 実践トレーニング | C17: 60 | D17: 7 | E17: 4 | F17: 4 | G17: 3
A18: 46238 | B18: 実践トレーニング | C18: 120 | D18: 7 | E18: 2 | F18: 2 | G18: 4 | H18: 移動疲れかも
A19: 46245 | B19: 実践トレーニング | C19: 60 | D19: 3 | E19: 4 | F19: 4 | G19: 2
A20: 46246 | B20: 休養日 | C20: 0 | D20: 1 | E20: 1 | F20: 1 | G20: 1
A21: 46247 | B21: 休養日 | C21: 0 | D21: 1 | E21: 1 | F21: 1 | G21: 1
A22: 46248 | B22: 実践トレーニング | C22: 180 | D22: 6 | E22: 4 | F22: 4 | G22: 3
A23: 46249 | B23: 実践トレーニング | C23: 60 | D23: 5 | E23: 4 | F23: 4 | G23: 3
A24: 46250 | B24: 実践トレーニング | C24: 180 | D24: 7 | E24: 4 | F24: 4 | G24: 3
A25: 46251 | B25: 実践トレーニング | C25: 120 | D25: 7 | E25: 4 | F25: 4 | G25: 3
A26: 46252 | B26: 実践トレーニング | C26: 90 | D26: 7 | E26: 3 | F26: 4 | G26: 4
A27: 46254 | B27: 実践トレーニング | C27: 120 | D27: 7 | E27: 4 | F27: 3 | G27: 4 | H27: 暑かった
A28: 46256 | B28: 実践トレーニング | C28: 60 | D28: 10 | E28: 3 | F28: 3 | G28: 3 | H28: 日福記録会 動きが遅くピッチが出なかったけど1発1発の伸びは大きかった
A29: 46257 | B29: 休養日 | C29: 0 | D29: 1 | E29: 1 | F29: 1 | G29: 1
A30: 46258 | B30: 休養日 | C30: 0 | D30: 1 | E30: 1 | F30: 1 | G30: 1
A31: 46259 | B31: 実践トレーニング | C31: 180 | D31: 7 | E31: 4 | F31: 3 | G31: 4
A32: 46260 | B32: 実践トレーニング | C32: 120 | D32: 6 | E32: 4 | F32: 3 | G32: 3
A33: 46261 | B33: 実践トレーニング | C33: 120 | D33: 7 | E33: 4 | F33: 3 | G33: 3
A34: 46262 | B34: 実践トレーニング | C34: 60 | D34: 5 | E34: 4 | F34: 4 | G34: 2
A35: 46263 | B35: 実践トレーニング | C35: 60 | D35: 5 | E35: 3 | F35: 3 | G35: 3
A36: 46264 | B36: 実践トレーニング | C36: 60 | D36: 7 | E36: 4 | F36: 4 | G36: 3
A37: 46265 | B37: 実践トレーニング | C37: 60 | D37: 6 | E37: 4 | F37: 4 | G37: 3
A38: 46266 | B38: 実践トレーニング | C38: 60 | D38: 5 | E38: 3 | F38: 4 | G38: 3
A39: 46267 | B39: 実践トレーニング | C39: 60 | D39: 5 | E39: 4 | F39: 4 | G39: 3
A40: 46268 | B40: 実践トレーニング | C40: 60 | D40: 5 | E40: 3 | F40: 3 | G40: 3
... A44: 46271 | B44: 実践トレーニング | C44: 60 | D44: 5 | E44: 3 | F44: 2 | G44: 4
...

Sheet データ_食事
A1: データ_食事
A3: 日付 | B3: 練習後補食 | C3: 栄養バランス | D3: 水分摂取量_ml | E3: きのこ海藻 | F3: 昼タンパク質_魚 | G3: 昼タンパク質_肉 | H3: 昼タンパク質_豆 | I3: 昼タンパク質_卵 | J3: 夕タンパク質_魚 | K3: 夕タンパク質_肉 | L3: 夕タンパク質_豆 | M3: 夕タンパク質_卵 | N3: メモ
A4: 46225 | B4: はい | C4: 3 | D4: 1000 | E4: はい | I4: ○ | K4: ○ | M4: ○
A5: 46226 | B5: いいえ | C5: 3 | D5: 1000 | E5: はい | G5: ○ | I5: ○ | J5: ○ | K5: ○ | M5: ○
A6: 46227 | B6: はい | C6: 2 | D6: 1000 | E6: はい | I6: ○ | K6: ○
A7: 46228 | B7: いいえ | C7: 3 | D7: 1000 | E7: はい | G7: ○ | K7: ○ | M7: ○
A8: 46229 | B8: はい | C8: 2 | D8: 1000 | E8: はい | F8: ○ | I8: ○ | K8: ○ | M8: ○
A9: 46230 | B9: はい | C9: 3 | D9: 1000 | E9: はい | K9: ○ | M9: ○
A10: 46231 | B10: はい | C10: 3 | D10: 1000 | E10: はい | G10: ○ | K10: ○ | M10: ○
A11: 46232 | B11: はい | C11: 3 | D11: 1000 | E11: はい | G11: ○ | K11: ○ | M11: ○
A12: 46233 | B12: はい | C12: 4 | D12: 1000 | E12: いいえ | G12: ○ | K12: ○
A13: 46234 | B13: いいえ | C13: 2 | D13: 1000 | E13: はい | G13: ○ | J13: ○ | K13: ○ | L13: ○
A14: 46235 | B14: はい | C14: 2 | D14: 1000 | E14: はい | G14: ○ | K14: ○ | L14: ○ | M14: ○
A15: 46236 | B15: はい | C15: 3 | D15: 1000 | E15: はい | G15: ○ | K15: ○ | M15: ○
A16: 46238 | B16: はい | C16: 2 | D16: 1500 | E16: いいえ | G16: ○ | H16: ○ | I16: ○ | K16: ○ | M16: ○
A17: 46245 | B17: はい | C17: 4 | D17: 1000 | E17: いいえ | G17: ○ | K17: ○ | L17: ○ | M17: ○
A18: 46246 | B18: いいえ | C18: 2 | D18: 1000 | E18: いいえ | I18: ○ | J18: ○ | L18: ○ | M18: ○
A19: 46247 | B19: いいえ | C19: 4 | D19: 500 | E19: いいえ | I19: ○ | K19: ○ | M19: ○
A20: 46248 | B20: いいえ | C20: 2 | D20: 1000 | E20: はい | I20: ○ | J20: ○ | K20: ○ | L20: ○ | M20: ○
A21: 46249 | B21: はい | C21: 3 | D21: 1000 | E21: はい | G21: ○ | J21: ○ | K21: ○ | L21: ○
A22: 46250 | B22: いいえ | C22: 4 | D22: 1000 | E22: はい | M22: ○
A23: 46251 | B23: はい | C23: 2 | D23: 1000 | E23: はい | G23: ○ | J23: ○ | K23: ○ | L23: ○
A24: 46252 | B24: いいえ | C24: 3 | D24: 1000 | E24: いいえ | K24: ○
A25: 46254 | B25: はい | C25: 1 | D25: 1000 | E25: はい | G25: ○ | K25: ○ | L25: ○ | M25: ○
A26: 46256 | B26: はい | C26: 4 | D26: 1000 | E26: いいえ | K26: ○
A27: 46257 | B27: いいえ | C27: 4 | D27: 500 | E27: はい | K27: ○ | L27: ○ | M27: ○
A28: 46258 | B28: いいえ | C28: 3 | D28: 1000 | E28: はい | G28: ○ | K28: ○
A29: 46259 | B29: はい | C29: 3 | D29: 1000 | E29: いいえ | G29: ○ | J29: ○
A30: 46260 | B30: はい | C30: 3 | D30: 1000 | E30: はい | J30: ○ | K30: ○ | L30: ○ | M30: ○
A31: 46261 | B31: はい | C31: 3 | D31: 500 | E31: はい | J31: ○ | K31: ○ | L31: ○ | M31: ○
A32: 46262 | B32: いいえ | C32: 3 | D32: 1000 | E32: はい | G32: ○ | K32: ○ | L32: ○
A33: 46263 | B33: はい | C33: 3 | D33: 1000 | E33: はい | G33: ○ | J33: ○ | K33: ○
A34: 46264 | B34: はい | C34: 3 | D34: 1000 | E34: はい | I34: ○ | J34: ○ | L34: ○
A35: 46265 | B35: はい | C35: 2 | D35: 1000 | E35: はい | G35: ○ | K35: ○ | L35: ○
A36: 46266 | B36: はい | C36: 2 | D36: 500 | E36: はい | G36: ○ | I36: ○ | K36: ○
A37: 46267 | B37: はい | C37: 3 | D37: 1000 | E37: はい | J37: ○ | K37: ○ | L37: ○
A38: 46268 | B38: はい | C38: 3 | D38: 1000 | E38: はい | G38: ○ | K38: ○ | L38: ○ | M38: ○
A39: 46269 | B39: はい | C39: 3 | D39: 1000 | E39: はい | J39: ○ | K39: ○ | L39: ○
A40: 46270 | B40: はい | C40: 3 | D40: 1000 | E40: はい | I40: ○ | K40: ○
A41: 46271 | B41: はい | C41: 3 | D41: 1000 | E41: はい | F41: ○ | K41: ○ | M41: ○
...
